Started by an SCM change
Running as SYSTEM
Building remotely on [8mha:////4MyCSz62rCYUJJ6n3DIvJraLDC4yccoQ2qnCvm9ORS2oAAAAmx+LCAAAAAAAAP9b85aBtbiIQTGjNKU4P08vOT+vOD8nVc83PyU1x6OyILUoJzMv2y+/JJUBAhiZGBgqihhk0NSjKDWzXb3RdlLBUSYGJk8GtpzUvPSSDB8G5tKinBIGIZ+sxLJE/ZzEvHT94JKizLx0a6BxUmjGOUNodHsLgAy2EgYB/eT83ILSktQi/TygO3WNAAHkn4LFAAAA[0mnode-2 in workspace /home/vagrant/workspace/Deploy/Build Test App
The recommended git tool is: NONE
No credentials specified
Cloning the remote Git repository
Cloning repository https://github.com/sleepychild/DevOpsPlaygroundTestApp.git
 > git init /home/vagrant/workspace/Deploy/Build Test App # timeout=10
Fetching upstream changes from https://github.com/sleepychild/DevOpsPlaygroundTestApp.git
 > git --version # timeout=10
 > git --version # 'git version 2.25.1'
 > git fetch --tags --force --progress -- https://github.com/sleepychild/DevOpsPlaygroundTestApp.git +refs/heads/*:refs/remotes/origin/* # timeout=10
 > git config remote.origin.url https://github.com/sleepychild/DevOpsPlaygroundTestApp.git # timeout=10
 > git config --add remote.origin.fetch +refs/heads/*:refs/remotes/origin/* # timeout=10
Avoid second fetch
 > git rev-parse refs/remotes/origin/main^{commit} # timeout=10
Checking out Revision 3c329f7e3a71836545c62b5c4ff3fb7b759e0e61 (refs/remotes/origin/main)
 > git config core.sparsecheckout # timeout=10
 > git checkout -f 3c329f7e3a71836545c62b5c4ff3fb7b759e0e61 # timeout=10
Commit message: "Update README.md"
 > git rev-list --no-walk 71316bedb0bc8161039dde1ed2a68312f3178baf # timeout=10
[Build Test App] $ /bin/sh -xe /tmp/jenkins15598028159277183834.sh
+ ./deploy.sh
[16879] Failed to execute script docker-compose
Traceback (most recent call last):
  File "urllib3/connectionpool.py", line 677, in urlopen
  File "urllib3/connectionpool.py", line 392, in _make_request
  File "http/client.py", line 1277, in request
  File "http/client.py", line 1323, in _send_request
  File "http/client.py", line 1272, in endheaders
  File "http/client.py", line 1032, in _send_output
  File "http/client.py", line 972, in send
  File "docker/transport/unixconn.py", line 43, in connect
PermissionError: [Errno 13] Permission denied

During handling of the above exception, another exception occurred:

Traceback (most recent call last):
  File "requests/adapters.py", line 449, in send
  File "urllib3/connectionpool.py", line 727, in urlopen
  File "urllib3/util/retry.py", line 410, in increment
  File "urllib3/packages/six.py", line 734, in reraise
  File "urllib3/connectionpool.py", line 677, in urlopen
  File "urllib3/connectionpool.py", line 392, in _make_request
  File "http/client.py", line 1277, in request
  File "http/client.py", line 1323, in _send_request
  File "http/client.py", line 1272, in endheaders
  File "http/client.py", line 1032, in _send_output
  File "http/client.py", line 972, in send
  File "docker/transport/unixconn.py", line 43, in connect
urllib3.exceptions.ProtocolError: ('Connection aborted.', PermissionError(13, 'Permission denied'))

During handling of the above exception, another exception occurred:

Traceback (most recent call last):
  File "docker/api/client.py", line 214, in _retrieve_server_version
  File "docker/api/daemon.py", line 181, in version
  File "docker/utils/decorators.py", line 46, in inner
  File "docker/api/client.py", line 237, in _get
  File "requests/sessions.py", line 543, in get
  File "requests/sessions.py", line 530, in request
  File "requests/sessions.py", line 643, in send
  File "requests/adapters.py", line 498, in send
requests.exceptions.ConnectionError: ('Connection aborted.', PermissionError(13, 'Permission denied'))

During handling of the above exception, another exception occurred:

Traceback (most recent call last):
  File "docker-compose", line 3, in <module>
  File "compose/cli/main.py", line 81, in main
  File "compose/cli/main.py", line 200, in perform_command
  File "compose/cli/command.py", line 70, in project_from_options
  File "compose/cli/command.py", line 153, in get_project
  File "compose/cli/docker_client.py", line 43, in get_client
  File "compose/cli/docker_client.py", line 170, in docker_client
  File "docker/api/client.py", line 197, in __init__
  File "docker/api/client.py", line 222, in _retrieve_server_version
docker.errors.DockerException: Error while fetching server API version: ('Connection aborted.', PermissionError(13, 'Permission denied'))
[16883] Failed to execute script docker-compose
Traceback (most recent call last):
  File "urllib3/connectionpool.py", line 677, in urlopen
  File "urllib3/connectionpool.py", line 392, in _make_request
  File "http/client.py", line 1277, in request
  File "http/client.py", line 1323, in _send_request
  File "http/client.py", line 1272, in endheaders
  File "http/client.py", line 1032, in _send_output
  File "http/client.py", line 972, in send
  File "docker/transport/unixconn.py", line 43, in connect
PermissionError: [Errno 13] Permission denied

During handling of the above exception, another exception occurred:

Traceback (most recent call last):
  File "requests/adapters.py", line 449, in send
  File "urllib3/connectionpool.py", line 727, in urlopen
  File "urllib3/util/retry.py", line 410, in increment
  File "urllib3/packages/six.py", line 734, in reraise
  File "urllib3/connectionpool.py", line 677, in urlopen
  File "urllib3/connectionpool.py", line 392, in _make_request
  File "http/client.py", line 1277, in request
  File "http/client.py", line 1323, in _send_request
  File "http/client.py", line 1272, in endheaders
  File "http/client.py", line 1032, in _send_output
  File "http/client.py", line 972, in send
  File "docker/transport/unixconn.py", line 43, in connect
urllib3.exceptions.ProtocolError: ('Connection aborted.', PermissionError(13, 'Permission denied'))

During handling of the above exception, another exception occurred:

Traceback (most recent call last):
  File "docker/api/client.py", line 214, in _retrieve_server_version
  File "docker/api/daemon.py", line 181, in version
  File "docker/utils/decorators.py", line 46, in inner
  File "docker/api/client.py", line 237, in _get
  File "requests/sessions.py", line 543, in get
  File "requests/sessions.py", line 530, in request
  File "requests/sessions.py", line 643, in send
  File "requests/adapters.py", line 498, in send
requests.exceptions.ConnectionError: ('Connection aborted.', PermissionError(13, 'Permission denied'))

During handling of the above exception, another exception occurred:

Traceback (most recent call last):
  File "docker-compose", line 3, in <module>
  File "compose/cli/main.py", line 81, in main
  File "compose/cli/main.py", line 200, in perform_command
  File "compose/cli/command.py", line 70, in project_from_options
  File "compose/cli/command.py", line 153, in get_project
  File "compose/cli/docker_client.py", line 43, in get_client
  File "compose/cli/docker_client.py", line 170, in docker_client
  File "docker/api/client.py", line 197, in __init__
  File "docker/api/client.py", line 222, in _retrieve_server_version
docker.errors.DockerException: Error while fetching server API version: ('Connection aborted.', PermissionError(13, 'Permission denied'))
Ignoring unsupported options: build, restart

Got permission denied while trying to connect to the Docker daemon socket at unix:///var/run/docker.sock: Get http://%2Fvar%2Frun%2Fdocker.sock/v1.24/info: dial unix /var/run/docker.sock: connect: permission denied
Build step 'Execute shell' marked build as failure
Finished: FAILURE
